#VRML_SIM R2023b utf8

EXTERNPROTO "https://raw.githubusercontent.com/cyberbotics/webots/R2023b/projects/objects/backgrounds/protos/TexturedBackground.proto"
EXTERNPROTO "https://raw.githubusercontent.com/cyberbotics/webots/R2023b/projects/objects/backgrounds/protos/TexturedBackgroundLight.proto"
EXTERNPROTO "https://raw.githubusercontent.com/cyberbotics/webots/R2023b/projects/objects/floors/protos/RectangleArena.proto"
IMPORTABLE EXTERNPROTO "https://raw.githubusercontent.com/cyberbotics/webots/R2023b/projects/objects/animals/protos/Cow.proto"
EXTERNPROTO "https://raw.githubusercontent.com/cyberbotics/webots/R2023b/projects/appearances/protos/Parquetry.proto"

WorldInfo {
  info [
    "The user drives a Supervisor by the Keyboard which drives slaves robots by using an emitter device."
  ]
  title "Omniscience"
}
Viewpoint {
  orientation -0.5773502691896258 0.5773502691896258 0.5773502691896258 2.0944
  position 1.396709991609021 1.56432409412641 8.657647288955209
}
TexturedBackground {
}
TexturedBackgroundLight {
}
DEF ROBOT1 Robot {
  translation 0.160083 0.57018 -0.000435664
  rotation 0.01415724815962243 -0.10961171786666567 0.9938736557686119 0
  children [
    DEF driver_emitter Emitter {
      name "driver_emitter"
      channel 4
      allowedChannels [
        4
      ]
    }
    DEF MAIN_BODY Pose {
      translation 0 0 0.0415
      children [
        Shape {
          appearance PBRAppearance {
            baseColor 0.0820075 0.364731 0.8
            roughness 1
            metalness 0
          }
          geometry DEF BODY Cylinder {
            height 0.08
            radius 0.045
          }
        }
      ]
    }
    HingeJoint {
      jointParameters HingeJointParameters {
        position 13754.298978713152
        axis 0 1 0
        anchor 0 0 0.025
      }
      device [
        RotationalMotor {
          name "left wheel motor"
        }
        PositionSensor {
          name "left wheel sensor"
        }
      ]
      endPoint DEF LEFT_WHEEL Solid {
        translation 0 0.04499999999999893 0.025
        rotation 0 1 0 1.7048566042166677
        children [
          DEF WHEEL Pose {
            rotation -1 0 0 1.57
            children [
              Shape {
                appearance PBRAppearance {
                  baseColor 1 0 0
                  roughness 1
                  metalness 0
                }
                geometry Cylinder {
                  height 0.01
                  radius 0.025
                }
              }
            ]
          }
        ]
        name "left wheel"
        boundingObject DEF WHEEL Pose {
          rotation -1 0 0 1.57
          children [
            Shape {
              appearance PBRAppearance {
                baseColor 1 0 0
                roughness 1
                metalness 0
              }
              geometry Cylinder {
                height 0.01
                radius 0.025
              }
            }
          ]
        }
        physics DEF PHYSICS_WHEEL Physics {
          density -1
          mass 0.05
        }
      }
    }
    HingeJoint {
      jointParameters HingeJointParameters {
        position 16281.126900159508
        axis 0 1 0
        anchor 0 0 0.025
      }
      device [
        RotationalMotor {
          name "right wheel motor"
        }
        PositionSensor {
          name "right wheel sensor"
        }
      ]
      endPoint DEF RIGHT_WHEEL Solid {
        translation 0 -0.044999999999994746 0.025
        rotation 0 1 0 3.089604564379325
        children [
          DEF WHEEL Pose {
            rotation -1 0 0 1.57
            children [
              Shape {
                appearance PBRAppearance {
                  baseColor 1 0 0
                  roughness 1
                  metalness 0
                }
                geometry Cylinder {
                  height 0.01
                  radius 0.025
                }
              }
            ]
          }
        ]
        name "right wheel"
        boundingObject USE WHEEL
        physics DEF PHYSICS_WHEEL Physics {
          density -1
          mass 0.05
        }
      }
    }
    DEF LEFT_EYE DistanceSensor {
      translation 0.042 0.02 0.063
      rotation 0 0 -1 -0.499205
      children [
        DEF INFRARED Pose {
          rotation 0.577656895078166 0.5771968951617173 -0.5771968951617173 -2.093935
          children [
            Shape {
              appearance PBRAppearance {
                baseColor 0.975691 0.981481 0.0252992
                roughness 1
                metalness 0
              }
              geometry Cylinder {
                height 0.004
                radius 0.008
              }
            }
          ]
        }
      ]
      name "ds0"
      lookupTable [
        0 1000 0
        0.15 500 0
        0.3 0 0
      ]
      numberOfRays 2
      aperture 1
    }
    DEF RIGHT_EYE DistanceSensor {
      translation 0.042 -0.02 0.063
      rotation 0 0 1 -0.500795
      children [
        DEF INFRARED Pose {
          rotation 0.577656895078166 0.5771968951617173 -0.5771968951617173 -2.093935
          children [
            Shape {
              appearance PBRAppearance {
                baseColor 0.975691 0.981481 0.0252992
                roughness 1
                metalness 0
              }
              geometry Cylinder {
                height 0.004
                radius 0.008
              }
            }
          ]
        }
      ]
      name "ds1"
      lookupTable [
        0 1000 0
        0.15 500 0
        0.3 0 0
      ]
      numberOfRays 2
      aperture 1
    }
    Receiver {
    }
    Camera {
      translation 0.045 0 0.045
      children [
        Pose {
          rotation 0 -1 0 1.57
          children [
            Shape {
              appearance PBRAppearance {
                baseColor 0.8 0.8 0.8
                roughness 1
                metalness 0
              }
              geometry Cylinder {
                height 0.01
                radius 0.007
              }
            }
          ]
        }
      ]
      fieldOfView 1.5
      recognition Recognition {
        maxRange 1
      }
    }
  ]
  name "robot1"
  boundingObject DEF MYBOT_BOUNDING Pose {
    translation 0 0 0.0415
    children [
      DEF BODY Cylinder {
        height 0.08
        radius 0.045
      }
    ]
  }
  physics DEF MYBOT_PHYSICS Physics {
    density -1
    mass 0.5
  }
  controller "<none>"
}
DEF ROBOT2 Robot {
  translation 0.152264 0.376849 -0.000451626
  rotation 0.01414629717336871 -0.1095801417532239 0.9938772936382168 0
  children [
    DEF driver_emitter Emitter {
      name "driver_emitter"
      channel 2
      allowedChannels [
        2
      ]
    }
    DEF MAIN_BODY Pose {
      translation 0 0 0.0415
      children [
        Shape {
          appearance PBRAppearance {
            baseColor 0.0820075 0.364731 0.8
            roughness 1
            metalness 0
          }
          geometry DEF BODY Cylinder {
            height 0.08
            radius 0.045
          }
        }
      ]
    }
    HingeJoint {
      jointParameters HingeJointParameters {
        position 14050.118707351845
        axis 0 1 0
        anchor 0 0 0.025
      }
      device [
        RotationalMotor {
          name "left wheel motor"
        }
        PositionSensor {
          name "left wheel sensor"
        }
      ]
      endPoint DEF LEFT_WHEEL Solid {
        translation 0 0.04499999999999887 0.025
        rotation 0 -1 0 4.068309501710432
        children [
          DEF WHEEL Pose {
            rotation -1 0 0 1.57
            children [
              Shape {
                appearance PBRAppearance {
                  baseColor 1 0 0
                  roughness 1
                  metalness 0
                }
                geometry Cylinder {
                  height 0.01
                  radius 0.025
                }
              }
            ]
          }
        ]
        name "left wheel"
        boundingObject DEF WHEEL Pose {
          rotation -1 0 0 1.57
          children [
            Shape {
              appearance PBRAppearance {
                baseColor 1 0 0
                roughness 1
                metalness 0
              }
              geometry Cylinder {
                height 0.01
                radius 0.025
              }
            }
          ]
        }
        physics DEF PHYSICS_WHEEL Physics {
          density -1
          mass 0.05
        }
      }
    }
    HingeJoint {
      jointParameters HingeJointParameters {
        position 16587.274819981223
        axis 0 1 0
        anchor 0 0 0.025
      }
      device [
        RotationalMotor {
          name "right wheel motor"
        }
        PositionSensor {
          name "right wheel sensor"
        }
      ]
      endPoint DEF RIGHT_WHEEL Solid {
        translation 0 -0.04500000000000042 0.025
        rotation 0 -1 0 4.921740972885178
        children [
          DEF WHEEL Pose {
            rotation -1 0 0 1.57
            children [
              Shape {
                appearance PBRAppearance {
                  baseColor 1 0 0
                  roughness 1
                  metalness 0
                }
                geometry Cylinder {
                  height 0.01
                  radius 0.025
                }
              }
            ]
          }
        ]
        name "right wheel"
        boundingObject USE WHEEL
        physics DEF PHYSICS_WHEEL Physics {
          density -1
          mass 0.05
        }
      }
    }
    DEF LEFT_EYE DistanceSensor {
      translation 0.042 0.02 0.063
      rotation 0 0 -1 -0.499205
      children [
        DEF INFRARED Pose {
          rotation 0.577656895078166 0.5771968951617173 -0.5771968951617173 -2.093935
          children [
            Shape {
              appearance PBRAppearance {
                baseColor 0.975691 0.981481 0.0252992
                roughness 1
                metalness 0
              }
              geometry Cylinder {
                height 0.004
                radius 0.008
              }
            }
          ]
        }
      ]
      name "ds0"
      lookupTable [
        0 1000 0
        0.15 500 0
        0.3 0 0
      ]
      numberOfRays 2
      aperture 1
    }
    DEF RIGHT_EYE DistanceSensor {
      translation 0.042 -0.02 0.063
      rotation 0 0 1 -0.500795
      children [
        DEF INFRARED Pose {
          rotation 0.577656895078166 0.5771968951617173 -0.5771968951617173 -2.093935
          children [
            Shape {
              appearance PBRAppearance {
                baseColor 0.975691 0.981481 0.0252992
                roughness 1
                metalness 0
              }
              geometry Cylinder {
                height 0.004
                radius 0.008
              }
            }
          ]
        }
      ]
      name "ds1"
      lookupTable [
        0 1000 0
        0.15 500 0
        0.3 0 0
      ]
      numberOfRays 2
      aperture 1
    }
    Receiver {
    }
    Camera {
      translation 0.045 0 0.045
      children [
        Pose {
          rotation 0 -1 0 1.57
          children [
            Shape {
              appearance PBRAppearance {
                baseColor 0.8 0.8 0.8
                roughness 1
                metalness 0
              }
              geometry Cylinder {
                height 0.01
                radius 0.007
              }
            }
          ]
        }
      ]
      fieldOfView 1.5
      recognition Recognition {
        maxRange 1
      }
    }
  ]
  name "robot2"
  boundingObject DEF MYBOT_BOUNDING Pose {
    translation 0 0 0.0415
    children [
      DEF BODY Cylinder {
        height 0.08
        radius 0.045
      }
    ]
  }
  physics DEF MYBOT_PHYSICS Physics {
    density -1
    mass 0.5
  }
  controller "slave2"
}
DEF ROBOT3 Robot {
  translation 0.15012 0.159863 -0.000244968
  rotation -0.0140906079945501 0.14599598453108986 0.9891848296790352 0
  children [
    DEF driver_emitter Emitter {
      name "driver_emitter"
      channel 3
      allowedChannels [
        3
      ]
    }
    DEF MAIN_BODY Pose {
      translation 0 0 0.0415
      children [
        Shape {
          appearance PBRAppearance {
            baseColor 0.0820075 0.364731 0.8
            roughness 1
            metalness 0
          }
          geometry DEF BODY Cylinder {
            height 0.08
            radius 0.045
          }
        }
      ]
    }
    HingeJoint {
      jointParameters HingeJointParameters {
        position 13901.216140993225
        axis 0 1 0
        anchor 0 0 0.025
      }
      device [
        RotationalMotor {
          name "left wheel motor"
        }
        PositionSensor {
          name "left wheel sensor"
        }
      ]
      endPoint DEF LEFT_WHEEL Solid {
        translation 0 0.04500000000000177 0.025
        rotation 0 -1 0 2.1744284880202347
        children [
          DEF WHEEL Pose {
            rotation -1 0 0 1.57
            children [
              Shape {
                appearance PBRAppearance {
                  baseColor 1 0 0
                  roughness 1
                  metalness 0
                }
                geometry Cylinder {
                  height 0.01
                  radius 0.025
                }
              }
            ]
          }
        ]
        name "left wheel"
        boundingObject DEF WHEEL Pose {
          rotation -1 0 0 1.57
          children [
            Shape {
              appearance PBRAppearance {
                baseColor 1 0 0
                roughness 1
                metalness 0
              }
              geometry Cylinder {
                height 0.01
                radius 0.025
              }
            }
          ]
        }
        physics DEF PHYSICS_WHEEL Physics {
          density -1
          mass 0.05
        }
      }
    }
    HingeJoint {
      jointParameters HingeJointParameters {
        position 16446.19006062269
        axis 0 1 0
        anchor 0 0 0.025
      }
      device [
        RotationalMotor {
          name "right wheel motor"
        }
        PositionSensor {
          name "right wheel sensor"
        }
      ]
      endPoint DEF RIGHT_WHEEL Solid {
        translation 0 -0.04499999999999745 0.025
        rotation 0 0.9999999999999999 0 4.789947040893596
        children [
          DEF WHEEL Pose {
            rotation -1 0 0 1.57
            children [
              Shape {
                appearance PBRAppearance {
                  baseColor 1 0 0
                  roughness 1
                  metalness 0
                }
                geometry Cylinder {
                  height 0.01
                  radius 0.025
                }
              }
            ]
          }
        ]
        name "right wheel"
        boundingObject USE WHEEL
        physics DEF PHYSICS_WHEEL Physics {
          density -1
          mass 0.05
        }
      }
    }
    DEF LEFT_EYE DistanceSensor {
      translation 0.042 0.02 0.063
      rotation 0 0 -1 -0.499205
      children [
        DEF INFRARED Pose {
          rotation 0.577656895078166 0.5771968951617173 -0.5771968951617173 -2.093935
          children [
            Shape {
              appearance PBRAppearance {
                baseColor 0.975691 0.981481 0.0252992
                roughness 1
                metalness 0
              }
              geometry Cylinder {
                height 0.004
                radius 0.008
              }
            }
          ]
        }
      ]
      name "ds0"
      lookupTable [
        0 1000 0
        0.15 500 0
        0.3 0 0
      ]
      numberOfRays 2
      aperture 1
    }
    DEF RIGHT_EYE DistanceSensor {
      translation 0.042 -0.02 0.063
      rotation 0 0 1 -0.500795
      children [
        DEF INFRARED Pose {
          rotation 0.577656895078166 0.5771968951617173 -0.5771968951617173 -2.093935
          children [
            Shape {
              appearance PBRAppearance {
                baseColor 0.975691 0.981481 0.0252992
                roughness 1
                metalness 0
              }
              geometry Cylinder {
                height 0.004
                radius 0.008
              }
            }
          ]
        }
      ]
      name "ds1"
      lookupTable [
        0 1000 0
        0.15 500 0
        0.3 0 0
      ]
      numberOfRays 2
      aperture 1
    }
    Receiver {
    }
    Camera {
      translation 0.045 0 0.045
      children [
        Pose {
          rotation 0 -1 0 1.57
          children [
            Shape {
              appearance PBRAppearance {
                baseColor 0.8 0.8 0.8
                roughness 1
                metalness 0
              }
              geometry Cylinder {
                height 0.01
                radius 0.007
              }
            }
          ]
        }
      ]
      fieldOfView 1.5
      recognition Recognition {
        maxRange 1
      }
    }
  ]
  name "robot3"
  boundingObject DEF MYBOT_BOUNDING Pose {
    translation 0 0 0.0415
    children [
      DEF BODY Cylinder {
        height 0.08
        radius 0.045
      }
    ]
  }
  physics DEF MYBOT_PHYSICS Physics {
    density -1
    mass 0.5
  }
  controller "<none>"
}
Robot {
  children [
    Receiver {
      channel 4
      allowedChannels [
        4
      ]
    }
    Receiver {
      name "receiver2"
      channel 2
      allowedChannels [
        2
      ]
    }
    Receiver {
      name "receiver3"
      channel 3
      allowedChannels [
        3
      ]
    }
    Emitter {
    }
  ]
  name "Driver"
  controller "driver"
  supervisor TRUE
}
Robot {
  translation 0.1 0 0.1
  name "Driver(1)"
  controller "<none>"
  supervisor TRUE
}
RectangleArena {
  translation 1.5 2 0
  floorSize 3 4
  floorAppearance Parquetry {
    type "chequered"
    colorOverride 0.7 0.7 0.4
  }
}
DEF Target Solid {
  translation 0.13 3.8775365266255046 0.0474241883119883
  rotation 1 1.9814171703777278e-15 1.0407235547122246e-14 0.006052703656311314
  children [
    Shape {
      appearance Parquetry {
        colorOverride 1 0 0
      }
      geometry Box {
        size 0.125 0.125 0.1
      }
    }
  ]
  name "solid(2)"
  boundingObject Box {
    size 0.25 0.25 0.1
  }
  physics Physics {
  }
  recognitionColors [
    1 0 0
  ]
}
DEF target2 Solid {
  translation 0.64 1.62 0.04933557007027372
  rotation 0.5525261887365437 0.11173763999540706 0.8259718582182604 9.43719255058658e-17
  children [
    Shape {
      appearance Parquetry {
        colorOverride 1 0 0
      }
      geometry Box {
        size 0.125 0.125 0.1
      }
    }
  ]
  name "solid(9)"
  boundingObject Box {
    size 0.125 0.125 0.1
  }
  physics Physics {
  }
  recognitionColors [
    1 0 0
  ]
}
DEF Wall Solid {
  translation 0.635585900371369 0.8799301526130017 0.03777803461218578
  rotation 0.6117083795819301 -0.7884291341321759 -0.06474842701438173 0.001312736054469996
  children [
    Shape {
      appearance Parquetry {
        type "light strip"
        IBLStrength 5
      }
      geometry Box {
        size 1.25 0.25 0.1
      }
    }
  ]
  boundingObject Box {
    size 1.25 0.25 0.1
  }
  physics Physics {
  }
}
DEF Wall6 Solid {
  translation 0.126077 2.88 0.047547535353326266
  rotation -4.827645339866759e-13 -3.9416597169409916e-14 -1 6.975172692853714e-05
  children [
    Shape {
      appearance Parquetry {
        type "light strip"
        IBLStrength 5
      }
      geometry Box {
        size 0.25 0.25 0.1
      }
    }
  ]
  name "solid(6)"
  boundingObject Box {
    size 0.25 0.25 0.1
  }
  physics Physics {
  }
}
DEF Wall2 Solid {
  translation 1.3756836495047686 1.6204317152498364 0.03274050934315356
  rotation 0.013865237566658896 0.013826222812727156 0.9998082769961212 1.5716351980672998
  children [
    Shape {
      appearance Parquetry {
        type "light strip"
        IBLStrength 5
      }
      geometry Box {
        size 1.75 0.25 0.1
      }
    }
  ]
  name "solid(1)"
  boundingObject Box {
    size 1.75 0.25 0.1
  }
  physics Physics {
  }
}
DEF Wall5 Solid {
  translation 0.8868823452696626 3.379882563764433 0.03674486112183189
  rotation -0.5775993845322063 -0.5770008032601246 0.5774504515758798 2.094735740583566
  children [
    Shape {
      appearance Parquetry {
        type "light strip"
        IBLStrength 5
      }
      geometry Box {
        size 1.25 0.1 0.25
      }
    }
  ]
  name "solid(5)"
  boundingObject Box {
    size 1.25 0.1 0.25
  }
  physics Physics {
  }
}
DEF Wall8 Solid {
  translation 2.870131521515128 3.119778196678308 0.047547512115837805
  rotation -4.38061985850823e-10 5.179276100601562e-10 1 3.13917842670979
  children [
    Shape {
      appearance Parquetry {
        type "light strip"
        IBLStrength 5
      }
      geometry Box {
        size 0.25 0.25 0.1
      }
    }
  ]
  name "solid(7)"
  boundingObject Box {
    size 0.25 0.25 0.1
  }
  physics Physics {
  }
}
DEF Wall7 Solid {
  translation 2.1300000000045674 3.498380000037078 0.0401900148334169
  rotation 1.6885202248898472e-15 1.22838651049571e-15 -0.9999999999999999 1.5707995090355333
  children [
    Shape {
      appearance Parquetry {
        type "light strip"
        IBLStrength 5
      }
      geometry Box {
        size 1 0.25 0.1
      }
    }
  ]
  name "solid(8)"
  boundingObject Box {
    size 1 0.25 0.1
  }
  physics Physics {
  }
}
DEF Wall3 Solid {
  translation 2.369446716055725 1.7499198208378435 0.03528501194120574
  rotation 5.872682148717553e-09 -5.8839698055939076e-09 -0.9999999999999999 1.5698635936714906
  children [
    Shape {
      appearance Parquetry {
        type "light strip"
        IBLStrength 5
      }
      geometry Box {
        size 1.5 0.25 0.1
      }
    }
  ]
  name "solid(3)"
  boundingObject Box {
    size 1.5 0.25 0.1
  }
  physics Physics {
  }
}
DEF Wall4 Solid {
  translation 2.7484850155185945 2.370025210301702 0.04509502585914406
  rotation -0.00019225139712832016 0.00017876401535419015 -0.9999999655414129 6.070575739342015e-06
  children [
    Shape {
      appearance Parquetry {
        type "light strip"
        IBLStrength 5
      }
      geometry Box {
        size 0.5 0.25 0.1
      }
    }
  ]
  name "solid(4)"
  boundingObject Box {
    size 0.5 0.25 0.1
  }
  physics Physics {
  }
}
